ERROR 2019-07-27 15:48:17,541 exception 135 Internal Server Error: /register/
Traceback (most recent call last):
  File "/home/python/.virtualenvs/new1/lib/python3.5/site-packages/django/template/utils.py", line 65, in __getitem__
    return self._engines[alias]
KeyError: 'django'

During handling of the above exception, another exception occurred:

Traceback (most recent call last):
  File "/home/python/.virtualenvs/new1/lib/python3.5/site-packages/django/core/handlers/exception.py", line 41, in inner
    response = get_response(request)
  File "/home/python/.virtualenvs/new1/lib/python3.5/site-packages/django/core/handlers/base.py", line 187, in _get_response
    response = self.process_exception_by_middleware(e, request)
  File "/home/python/.virtualenvs/new1/lib/python3.5/site-packages/django/core/handlers/base.py", line 185, in _get_response
    response = wrapped_callback(request, *callback_args, **callback_kwargs)
  File "/home/python/.virtualenvs/new1/lib/python3.5/site-packages/django/views/generic/base.py", line 68, in view
    return self.dispatch(request, *args, **kwargs)
  File "/home/python/.virtualenvs/new1/lib/python3.5/site-packages/django/views/generic/base.py", line 88, in dispatch
    return handler(request, *args, **kwargs)
  File "/home/python/Desktop/meiduo/meiduo_project/meiduo1/apps/users/views.py", line 8, in get
    return render(request, 'register.html')
  File "/home/python/.virtualenvs/new1/lib/python3.5/site-packages/django/shortcuts.py", line 30, in render
    content = loader.render_to_string(template_name, context, request, using=using)
  File "/home/python/.virtualenvs/new1/lib/python3.5/site-packages/django/template/loader.py", line 67, in render_to_string
    template = get_template(template_name, using=using)
  File "/home/python/.virtualenvs/new1/lib/python3.5/site-packages/django/template/loader.py", line 18, in get_template
    engines = _engine_list(using)
  File "/home/python/.virtualenvs/new1/lib/python3.5/site-packages/django/template/loader.py", line 72, in _engine_list
    return engines.all() if using is None else [engines[using]]
  File "/home/python/.virtualenvs/new1/lib/python3.5/site-packages/django/template/utils.py", line 89, in all
    return [self[alias] for alias in self]
  File "/home/python/.virtualenvs/new1/lib/python3.5/site-packages/django/template/utils.py", line 89, in <listcomp>
    return [self[alias] for alias in self]
  File "/home/python/.virtualenvs/new1/lib/python3.5/site-packages/django/template/utils.py", line 80, in __getitem__
    engine = engine_cls(params)
  File "/home/python/.virtualenvs/new1/lib/python3.5/site-packages/django/template/backends/django.py", line 32, in __init__
    self.engine = Engine(self.dirs, self.app_dirs, **options)
TypeError: __init__() got an unexpected keyword argument 'environment'
ERROR 2019-07-27 15:48:17,599 basehttp 124 "GET /register/ HTTP/1.1" 500 123484
ERROR 2019-07-27 16:09:53,115 exception 135 Internal Server Error: /register/
Traceback (most recent call last):
  File "/home/python/.virtualenvs/new1/lib/python3.5/site-packages/django/template/utils.py", line 65, in __getitem__
    return self._engines[alias]
KeyError: 'django'

During handling of the above exception, another exception occurred:

Traceback (most recent call last):
  File "/home/python/.virtualenvs/new1/lib/python3.5/site-packages/django/core/handlers/exception.py", line 41, in inner
    response = get_response(request)
  File "/home/python/.virtualenvs/new1/lib/python3.5/site-packages/django/core/handlers/base.py", line 187, in _get_response
    response = self.process_exception_by_middleware(e, request)
  File "/home/python/.virtualenvs/new1/lib/python3.5/site-packages/django/core/handlers/base.py", line 185, in _get_response
    response = wrapped_callback(request, *callback_args, **callback_kwargs)
  File "/home/python/.virtualenvs/new1/lib/python3.5/site-packages/django/views/generic/base.py", line 68, in view
    return self.dispatch(request, *args, **kwargs)
  File "/home/python/.virtualenvs/new1/lib/python3.5/site-packages/django/views/generic/base.py", line 88, in dispatch
    return handler(request, *args, **kwargs)
  File "/home/python/Desktop/meiduo/meiduo_project/meiduo1/apps/users/views.py", line 8, in get
    return render(request, 'register.html')
  File "/home/python/.virtualenvs/new1/lib/python3.5/site-packages/django/shortcuts.py", line 30, in render
    content = loader.render_to_string(template_name, context, request, using=using)
  File "/home/python/.virtualenvs/new1/lib/python3.5/site-packages/django/template/loader.py", line 67, in render_to_string
    template = get_template(template_name, using=using)
  File "/home/python/.virtualenvs/new1/lib/python3.5/site-packages/django/template/loader.py", line 18, in get_template
    engines = _engine_list(using)
  File "/home/python/.virtualenvs/new1/lib/python3.5/site-packages/django/template/loader.py", line 72, in _engine_list
    return engines.all() if using is None else [engines[using]]
  File "/home/python/.virtualenvs/new1/lib/python3.5/site-packages/django/template/utils.py", line 89, in all
    return [self[alias] for alias in self]
  File "/home/python/.virtualenvs/new1/lib/python3.5/site-packages/django/template/utils.py", line 89, in <listcomp>
    return [self[alias] for alias in self]
  File "/home/python/.virtualenvs/new1/lib/python3.5/site-packages/django/template/utils.py", line 80, in __getitem__
    engine = engine_cls(params)
  File "/home/python/.virtualenvs/new1/lib/python3.5/site-packages/django/template/backends/django.py", line 32, in __init__
    self.engine = Engine(self.dirs, self.app_dirs, **options)
TypeError: __init__() got an unexpected keyword argument 'environment'
ERROR 2019-07-27 16:09:53,177 basehttp 124 "GET /register/ HTTP/1.1" 500 123484
ERROR 2019-07-27 16:32:27,992 exception 135 Internal Server Error: /register/
Traceback (most recent call last):
  File "/home/python/.virtualenvs/new1/lib/python3.5/site-packages/django/template/utils.py", line 65, in __getitem__
    return self._engines[alias]
KeyError: 'django'

During handling of the above exception, another exception occurred:

Traceback (most recent call last):
  File "/home/python/.virtualenvs/new1/lib/python3.5/site-packages/django/core/handlers/exception.py", line 41, in inner
    response = get_response(request)
  File "/home/python/.virtualenvs/new1/lib/python3.5/site-packages/django/core/handlers/base.py", line 187, in _get_response
    response = self.process_exception_by_middleware(e, request)
  File "/home/python/.virtualenvs/new1/lib/python3.5/site-packages/django/core/handlers/base.py", line 185, in _get_response
    response = wrapped_callback(request, *callback_args, **callback_kwargs)
  File "/home/python/.virtualenvs/new1/lib/python3.5/site-packages/django/views/generic/base.py", line 68, in view
    return self.dispatch(request, *args, **kwargs)
  File "/home/python/.virtualenvs/new1/lib/python3.5/site-packages/django/views/generic/base.py", line 88, in dispatch
    return handler(request, *args, **kwargs)
  File "/home/python/Desktop/meiduo/meiduo_project/meiduo1/apps/users/views.py", line 8, in get
    return render(request, 'register.html')
  File "/home/python/.virtualenvs/new1/lib/python3.5/site-packages/django/shortcuts.py", line 30, in render
    content = loader.render_to_string(template_name, context, request, using=using)
  File "/home/python/.virtualenvs/new1/lib/python3.5/site-packages/django/template/loader.py", line 67, in render_to_string
    template = get_template(template_name, using=using)
  File "/home/python/.virtualenvs/new1/lib/python3.5/site-packages/django/template/loader.py", line 18, in get_template
    engines = _engine_list(using)
  File "/home/python/.virtualenvs/new1/lib/python3.5/site-packages/django/template/loader.py", line 72, in _engine_list
    return engines.all() if using is None else [engines[using]]
  File "/home/python/.virtualenvs/new1/lib/python3.5/site-packages/django/template/utils.py", line 89, in all
    return [self[alias] for alias in self]
  File "/home/python/.virtualenvs/new1/lib/python3.5/site-packages/django/template/utils.py", line 89, in <listcomp>
    return [self[alias] for alias in self]
  File "/home/python/.virtualenvs/new1/lib/python3.5/site-packages/django/template/utils.py", line 80, in __getitem__
    engine = engine_cls(params)
  File "/home/python/.virtualenvs/new1/lib/python3.5/site-packages/django/template/backends/django.py", line 32, in __init__
    self.engine = Engine(self.dirs, self.app_dirs, **options)
TypeError: __init__() got an unexpected keyword argument 'environment'
ERROR 2019-07-27 16:32:28,055 basehttp 124 "GET /register/ HTTP/1.1" 500 123460
ERROR 2019-07-27 16:34:59,315 exception 135 Internal Server Error: /register/
Traceback (most recent call last):
  File "/home/python/.virtualenvs/new1/lib/python3.5/site-packages/django/template/utils.py", line 65, in __getitem__
    return self._engines[alias]
KeyError: 'django'

During handling of the above exception, another exception occurred:

Traceback (most recent call last):
  File "/home/python/.virtualenvs/new1/lib/python3.5/site-packages/django/core/handlers/exception.py", line 41, in inner
    response = get_response(request)
  File "/home/python/.virtualenvs/new1/lib/python3.5/site-packages/django/core/handlers/base.py", line 187, in _get_response
    response = self.process_exception_by_middleware(e, request)
  File "/home/python/.virtualenvs/new1/lib/python3.5/site-packages/django/core/handlers/base.py", line 185, in _get_response
    response = wrapped_callback(request, *callback_args, **callback_kwargs)
  File "/home/python/.virtualenvs/new1/lib/python3.5/site-packages/django/views/generic/base.py", line 68, in view
    return self.dispatch(request, *args, **kwargs)
  File "/home/python/.virtualenvs/new1/lib/python3.5/site-packages/django/views/generic/base.py", line 88, in dispatch
    return handler(request, *args, **kwargs)
  File "/home/python/Desktop/meiduo/meiduo_project/meiduo1/apps/users/views.py", line 8, in get
    return render(request, 'register.html')
  File "/home/python/.virtualenvs/new1/lib/python3.5/site-packages/django/shortcuts.py", line 30, in render
    content = loader.render_to_string(template_name, context, request, using=using)
  File "/home/python/.virtualenvs/new1/lib/python3.5/site-packages/django/template/loader.py", line 67, in render_to_string
    template = get_template(template_name, using=using)
  File "/home/python/.virtualenvs/new1/lib/python3.5/site-packages/django/template/loader.py", line 18, in get_template
    engines = _engine_list(using)
  File "/home/python/.virtualenvs/new1/lib/python3.5/site-packages/django/template/loader.py", line 72, in _engine_list
    return engines.all() if using is None else [engines[using]]
  File "/home/python/.virtualenvs/new1/lib/python3.5/site-packages/django/template/utils.py", line 89, in all
    return [self[alias] for alias in self]
  File "/home/python/.virtualenvs/new1/lib/python3.5/site-packages/django/template/utils.py", line 89, in <listcomp>
    return [self[alias] for alias in self]
  File "/home/python/.virtualenvs/new1/lib/python3.5/site-packages/django/template/utils.py", line 80, in __getitem__
    engine = engine_cls(params)
  File "/home/python/.virtualenvs/new1/lib/python3.5/site-packages/django/template/backends/django.py", line 32, in __init__
    self.engine = Engine(self.dirs, self.app_dirs, **options)
TypeError: __init__() got an unexpected keyword argument 'environment'
ERROR 2019-07-27 16:34:59,394 basehttp 124 "GET /register/ HTTP/1.1" 500 123460
ERROR 2019-07-27 16:36:37,897 exception 135 Internal Server Error: /register/
Traceback (most recent call last):
  File "/home/python/.virtualenvs/new1/lib/python3.5/site-packages/django/template/utils.py", line 65, in __getitem__
    return self._engines[alias]
KeyError: 'django'

During handling of the above exception, another exception occurred:

Traceback (most recent call last):
  File "/home/python/.virtualenvs/new1/lib/python3.5/site-packages/django/core/handlers/exception.py", line 41, in inner
    response = get_response(request)
  File "/home/python/.virtualenvs/new1/lib/python3.5/site-packages/django/core/handlers/base.py", line 187, in _get_response
    response = self.process_exception_by_middleware(e, request)
  File "/home/python/.virtualenvs/new1/lib/python3.5/site-packages/django/core/handlers/base.py", line 185, in _get_response
    response = wrapped_callback(request, *callback_args, **callback_kwargs)
  File "/home/python/.virtualenvs/new1/lib/python3.5/site-packages/django/views/generic/base.py", line 68, in view
    return self.dispatch(request, *args, **kwargs)
  File "/home/python/.virtualenvs/new1/lib/python3.5/site-packages/django/views/generic/base.py", line 88, in dispatch
    return handler(request, *args, **kwargs)
  File "/home/python/Desktop/meiduo/meiduo_project/meiduo1/apps/users/views.py", line 8, in get
    return render(request, 'register.html')
  File "/home/python/.virtualenvs/new1/lib/python3.5/site-packages/django/shortcuts.py", line 30, in render
    content = loader.render_to_string(template_name, context, request, using=using)
  File "/home/python/.virtualenvs/new1/lib/python3.5/site-packages/django/template/loader.py", line 67, in render_to_string
    template = get_template(template_name, using=using)
  File "/home/python/.virtualenvs/new1/lib/python3.5/site-packages/django/template/loader.py", line 18, in get_template
    engines = _engine_list(using)
  File "/home/python/.virtualenvs/new1/lib/python3.5/site-packages/django/template/loader.py", line 72, in _engine_list
    return engines.all() if using is None else [engines[using]]
  File "/home/python/.virtualenvs/new1/lib/python3.5/site-packages/django/template/utils.py", line 89, in all
    return [self[alias] for alias in self]
  File "/home/python/.virtualenvs/new1/lib/python3.5/site-packages/django/template/utils.py", line 89, in <listcomp>
    return [self[alias] for alias in self]
  File "/home/python/.virtualenvs/new1/lib/python3.5/site-packages/django/template/utils.py", line 80, in __getitem__
    engine = engine_cls(params)
  File "/home/python/.virtualenvs/new1/lib/python3.5/site-packages/django/template/backends/django.py", line 32, in __init__
    self.engine = Engine(self.dirs, self.app_dirs, **options)
TypeError: __init__() got an unexpected keyword argument 'environment'
ERROR 2019-07-27 16:36:37,963 basehttp 124 "GET /register/ HTTP/1.1" 500 123460
ERROR 2019-07-27 16:37:39,759 exception 135 Internal Server Error: /register/
Traceback (most recent call last):
  File "/home/python/.virtualenvs/new1/lib/python3.5/site-packages/django/template/utils.py", line 65, in __getitem__
    return self._engines[alias]
KeyError: 'django'

During handling of the above exception, another exception occurred:

Traceback (most recent call last):
  File "/home/python/.virtualenvs/new1/lib/python3.5/site-packages/django/core/handlers/exception.py", line 41, in inner
    response = get_response(request)
  File "/home/python/.virtualenvs/new1/lib/python3.5/site-packages/django/core/handlers/base.py", line 187, in _get_response
    response = self.process_exception_by_middleware(e, request)
  File "/home/python/.virtualenvs/new1/lib/python3.5/site-packages/django/core/handlers/base.py", line 185, in _get_response
    response = wrapped_callback(request, *callback_args, **callback_kwargs)
  File "/home/python/.virtualenvs/new1/lib/python3.5/site-packages/django/views/generic/base.py", line 68, in view
    return self.dispatch(request, *args, **kwargs)
  File "/home/python/.virtualenvs/new1/lib/python3.5/site-packages/django/views/generic/base.py", line 88, in dispatch
    return handler(request, *args, **kwargs)
  File "/home/python/Desktop/meiduo/meiduo_project/meiduo1/apps/users/views.py", line 8, in get
    return render(request, 'register.html')
  File "/home/python/.virtualenvs/new1/lib/python3.5/site-packages/django/shortcuts.py", line 30, in render
    content = loader.render_to_string(template_name, context, request, using=using)
  File "/home/python/.virtualenvs/new1/lib/python3.5/site-packages/django/template/loader.py", line 67, in render_to_string
    template = get_template(template_name, using=using)
  File "/home/python/.virtualenvs/new1/lib/python3.5/site-packages/django/template/loader.py", line 18, in get_template
    engines = _engine_list(using)
  File "/home/python/.virtualenvs/new1/lib/python3.5/site-packages/django/template/loader.py", line 72, in _engine_list
    return engines.all() if using is None else [engines[using]]
  File "/home/python/.virtualenvs/new1/lib/python3.5/site-packages/django/template/utils.py", line 89, in all
    return [self[alias] for alias in self]
  File "/home/python/.virtualenvs/new1/lib/python3.5/site-packages/django/template/utils.py", line 89, in <listcomp>
    return [self[alias] for alias in self]
  File "/home/python/.virtualenvs/new1/lib/python3.5/site-packages/django/template/utils.py", line 80, in __getitem__
    engine = engine_cls(params)
  File "/home/python/.virtualenvs/new1/lib/python3.5/site-packages/django/template/backends/django.py", line 32, in __init__
    self.engine = Engine(self.dirs, self.app_dirs, **options)
TypeError: __init__() got an unexpected keyword argument 'environment'
ERROR 2019-07-27 16:37:39,836 basehttp 124 "GET /register/ HTTP/1.1" 500 123460
ERROR 2019-07-27 16:37:41,876 exception 135 Internal Server Error: /register/
Traceback (most recent call last):
  File "/home/python/.virtualenvs/new1/lib/python3.5/site-packages/django/template/utils.py", line 65, in __getitem__
    return self._engines[alias]
KeyError: 'django'

During handling of the above exception, another exception occurred:

Traceback (most recent call last):
  File "/home/python/.virtualenvs/new1/lib/python3.5/site-packages/django/core/handlers/exception.py", line 41, in inner
    response = get_response(request)
  File "/home/python/.virtualenvs/new1/lib/python3.5/site-packages/django/core/handlers/base.py", line 187, in _get_response
    response = self.process_exception_by_middleware(e, request)
  File "/home/python/.virtualenvs/new1/lib/python3.5/site-packages/django/core/handlers/base.py", line 185, in _get_response
    response = wrapped_callback(request, *callback_args, **callback_kwargs)
  File "/home/python/.virtualenvs/new1/lib/python3.5/site-packages/django/views/generic/base.py", line 68, in view
    return self.dispatch(request, *args, **kwargs)
  File "/home/python/.virtualenvs/new1/lib/python3.5/site-packages/django/views/generic/base.py", line 88, in dispatch
    return handler(request, *args, **kwargs)
  File "/home/python/Desktop/meiduo/meiduo_project/meiduo1/apps/users/views.py", line 8, in get
    return render(request, 'register.html')
  File "/home/python/.virtualenvs/new1/lib/python3.5/site-packages/django/shortcuts.py", line 30, in render
    content = loader.render_to_string(template_name, context, request, using=using)
  File "/home/python/.virtualenvs/new1/lib/python3.5/site-packages/django/template/loader.py", line 67, in render_to_string
    template = get_template(template_name, using=using)
  File "/home/python/.virtualenvs/new1/lib/python3.5/site-packages/django/template/loader.py", line 18, in get_template
    engines = _engine_list(using)
  File "/home/python/.virtualenvs/new1/lib/python3.5/site-packages/django/template/loader.py", line 72, in _engine_list
    return engines.all() if using is None else [engines[using]]
  File "/home/python/.virtualenvs/new1/lib/python3.5/site-packages/django/template/utils.py", line 89, in all
    return [self[alias] for alias in self]
  File "/home/python/.virtualenvs/new1/lib/python3.5/site-packages/django/template/utils.py", line 89, in <listcomp>
    return [self[alias] for alias in self]
  File "/home/python/.virtualenvs/new1/lib/python3.5/site-packages/django/template/utils.py", line 80, in __getitem__
    engine = engine_cls(params)
  File "/home/python/.virtualenvs/new1/lib/python3.5/site-packages/django/template/backends/django.py", line 32, in __init__
    self.engine = Engine(self.dirs, self.app_dirs, **options)
TypeError: __init__() got an unexpected keyword argument 'environment'
ERROR 2019-07-27 16:37:41,946 basehttp 124 "GET /register/ HTTP/1.1" 500 123460
ERROR 2019-07-27 21:40:11,191 exception 135 Internal Server Error: /register/
Traceback (most recent call last):
  File "/home/python/.virtualenvs/new1/lib/python3.5/site-packages/django/core/handlers/exception.py", line 41, in inner
    response = get_response(request)
  File "/home/python/.virtualenvs/new1/lib/python3.5/site-packages/django/core/handlers/base.py", line 198, in _get_response
    "returned None instead." % (callback.__module__, view_name)
ValueError: The view users.views.RegisterView didn't return an HttpResponse object. It returned None instead.
ERROR 2019-07-27 21:40:11,228 basehttp 124 "POST /register/ HTTP/1.1" 500 65369
ERROR 2019-07-27 21:40:27,060 exception 135 Internal Server Error: /register/
Traceback (most recent call last):
  File "/home/python/.virtualenvs/new1/lib/python3.5/site-packages/django/core/handlers/exception.py", line 41, in inner
    response = get_response(request)
  File "/home/python/.virtualenvs/new1/lib/python3.5/site-packages/django/core/handlers/base.py", line 198, in _get_response
    "returned None instead." % (callback.__module__, view_name)
ValueError: The view users.views.RegisterView didn't return an HttpResponse object. It returned None instead.
ERROR 2019-07-27 21:40:27,086 basehttp 124 "POST /register/ HTTP/1.1" 500 65369
ERROR 2019-07-27 21:40:27,596 exception 135 Internal Server Error: /register/
Traceback (most recent call last):
  File "/home/python/.virtualenvs/new1/lib/python3.5/site-packages/django/core/handlers/exception.py", line 41, in inner
    response = get_response(request)
  File "/home/python/.virtualenvs/new1/lib/python3.5/site-packages/django/core/handlers/base.py", line 198, in _get_response
    "returned None instead." % (callback.__module__, view_name)
ValueError: The view users.views.RegisterView didn't return an HttpResponse object. It returned None instead.
ERROR 2019-07-27 21:40:27,621 basehttp 124 "POST /register/ HTTP/1.1" 500 65369
ERROR 2019-07-27 21:40:27,943 exception 135 Internal Server Error: /register/
Traceback (most recent call last):
  File "/home/python/.virtualenvs/new1/lib/python3.5/site-packages/django/core/handlers/exception.py", line 41, in inner
    response = get_response(request)
  File "/home/python/.virtualenvs/new1/lib/python3.5/site-packages/django/core/handlers/base.py", line 198, in _get_response
    "returned None instead." % (callback.__module__, view_name)
ValueError: The view users.views.RegisterView didn't return an HttpResponse object. It returned None instead.
ERROR 2019-07-27 21:40:27,967 basehttp 124 "POST /register/ HTTP/1.1" 500 65369
ERROR 2019-07-27 21:40:28,118 exception 135 Internal Server Error: /register/
Traceback (most recent call last):
  File "/home/python/.virtualenvs/new1/lib/python3.5/site-packages/django/core/handlers/exception.py", line 41, in inner
    response = get_response(request)
  File "/home/python/.virtualenvs/new1/lib/python3.5/site-packages/django/core/handlers/base.py", line 198, in _get_response
    "returned None instead." % (callback.__module__, view_name)
ValueError: The view users.views.RegisterView didn't return an HttpResponse object. It returned None instead.
ERROR 2019-07-27 21:40:28,144 basehttp 124 "POST /register/ HTTP/1.1" 500 65369
ERROR 2019-07-27 21:40:28,271 exception 135 Internal Server Error: /register/
Traceback (most recent call last):
  File "/home/python/.virtualenvs/new1/lib/python3.5/site-packages/django/core/handlers/exception.py", line 41, in inner
    response = get_response(request)
  File "/home/python/.virtualenvs/new1/lib/python3.5/site-packages/django/core/handlers/base.py", line 198, in _get_response
    "returned None instead." % (callback.__module__, view_name)
ValueError: The view users.views.RegisterView didn't return an HttpResponse object. It returned None instead.
ERROR 2019-07-27 21:40:28,297 basehttp 124 "POST /register/ HTTP/1.1" 500 65369
ERROR 2019-07-27 21:40:28,404 exception 135 Internal Server Error: /register/
Traceback (most recent call last):
  File "/home/python/.virtualenvs/new1/lib/python3.5/site-packages/django/core/handlers/exception.py", line 41, in inner
    response = get_response(request)
  File "/home/python/.virtualenvs/new1/lib/python3.5/site-packages/django/core/handlers/base.py", line 198, in _get_response
    "returned None instead." % (callback.__module__, view_name)
ValueError: The view users.views.RegisterView didn't return an HttpResponse object. It returned None instead.
ERROR 2019-07-27 21:40:28,427 basehttp 124 "POST /register/ HTTP/1.1" 500 65369
ERROR 2019-07-27 21:40:28,564 exception 135 Internal Server Error: /register/
Traceback (most recent call last):
  File "/home/python/.virtualenvs/new1/lib/python3.5/site-packages/django/core/handlers/exception.py", line 41, in inner
    response = get_response(request)
  File "/home/python/.virtualenvs/new1/lib/python3.5/site-packages/django/core/handlers/base.py", line 198, in _get_response
    "returned None instead." % (callback.__module__, view_name)
ValueError: The view users.views.RegisterView didn't return an HttpResponse object. It returned None instead.
ERROR 2019-07-27 21:40:28,588 basehttp 124 "POST /register/ HTTP/1.1" 500 65369
ERROR 2019-07-27 21:43:26,841 exception 135 Internal Server Error: /register/
Traceback (most recent call last):
  File "/home/python/.virtualenvs/new1/lib/python3.5/site-packages/django/core/handlers/exception.py", line 41, in inner
    response = get_response(request)
  File "/home/python/.virtualenvs/new1/lib/python3.5/site-packages/django/core/handlers/base.py", line 198, in _get_response
    "returned None instead." % (callback.__module__, view_name)
ValueError: The view users.views.RegisterView didn't return an HttpResponse object. It returned None instead.
ERROR 2019-07-27 21:43:26,872 basehttp 124 "POST /register/ HTTP/1.1" 500 65200
